Workbook
Name _Excel_BuiltIn__FilterDatabase_1_1_1 1: #REF!
Name _Excel_BuiltIn__FilterDatabase_1_1_1_1_1 1: #REF!
Name _Excel_BuiltIn__FilterDatabase_2_1 1: #REF!
Name _Excel_BuiltIn__FilterDatabase_3_1_1 1: #REF!
Name _Excel_BuiltIn__FilterDatabase_3_1_1_1 1: #REF!
Name _Excel_BuiltIn__FilterDatabase_4 1: #REF!
Name _Excel_BuiltIn__FilterDatabase_5 1: #REF!
Name _Excel_BuiltIn__FilterDatabase_5_1 1: #REF!
Name _Excel_BuiltIn__FilterDatabase_6 1: #REF!
Name COL_STAV_SKLADU: '04.02 - 10.02'!$O$6
Name Excel_BuiltIn__FilterDatabase_1: #REF!
Name Excel_BuiltIn__FilterDatabase_1_1: #REF!
Name Excel_BuiltIn__FilterDatabase_1_1_1: #REF!
Name Excel_BuiltIn__FilterDatabase_1_1_1_1: #REF!
Name Excel_BuiltIn__FilterDatabase_1_1_1_1_1: #REF!
Name Excel_BuiltIn__FilterDatabase_2: #REF!
Name Excel_BuiltIn__FilterDatabase_2_1: #REF!
Name Excel_BuiltIn__FilterDatabase_2_1_1: #REF!
Name Excel_BuiltIn__FilterDatabase_3_1: #REF!
Name Excel_BuiltIn__FilterDatabase_3_1_1: #REF!
Name Excel_BuiltIn__FilterDatabase_3_1_1_1: #REF!
Name Excel_BuiltIn__FilterDatabase_3_1_1_1_1: #REF!
Name Excel_BuiltIn__FilterDatabase_4: #REF!
Name Excel_BuiltIn__FilterDatabase_4_1: #REF!
Name Excel_BuiltIn__FilterDatabase_4_1_1: #REF!
Name Excel_BuiltIn__FilterDatabase_4_1_1_1: #REF!
Name Excel_BuiltIn__FilterDatabase_4_1_1_1_1: #REF!
Name Excel_BuiltIn__FilterDatabase_5: #REF!
Name Excel_BuiltIn__FilterDatabase_5_1: #REF!
Name Excel_BuiltIn__FilterDatabase_5_1_1: #REF!
Name Excel_BuiltIn__FilterDatabase_5_1_1_1: #REF!
Name Excel_BuiltIn__FilterDatabase_6: #REF!
Name Excel_BuiltIn__FilterDatabase_6_1: #REF!
Name Excel_BuiltIn__FilterDatabase_7: #REF!
Name Excel_BuiltIn__FilterDatabase_7_1: #REF!
Name Excel_BuiltIn__FilterDatabase_8: #REF!
Name Excel_BuiltIn__FilterDatabase_8_1: #REF!
Name Excel_BuiltIn_FilterDatabase: #REF!
Name Excel_BuiltIn_FilterDatabase1: #REF!
Name Excel_BuiltIn_FilterDatase_3: #REF!
Name excl01: [1]data!$A$1:$A$94
Name exclusive01: [1]data!$A$1:$A$93
Name KURZ: #REF!

Sheet 04.02 - 10.02
B1: LETÁK | U1: S:\TAMDA - MARKETING$\@REKLAMA$\News
B2: Číslo Letáku | C2: 1
E3: Začátek | F3: 46057 | S3: Hlavní téma | T3: Valentýn – sladké dárky & káva (start)
E4: Konec | F4: =F3+6 -> 46063 | N4: 40 | O4: druhotka tổng | S4: Micro téma | T4: Čokoládový týden
N5: =SUM(N7:N639) -> #VALUE! | O5: đã dùng | S5: Sezóna | T5: Zima
B6: EAN Kód | D6: Název zboží | E6: doplněk názvu / druhy | F6: gramáž / litráž | G6: EANY | H6: ACS | I6: NCS | J6: Název dodavatele | K6: Int. Kód | L6: HERO | M6: F, V, M | N6: PALETY | O6: STAV SKLADU | P6: BRNO | Q6: ÚSTÍ | R6: GIA AKCE | S6: blok | T6: Manager | U6: téma | V6: page | W6: cena od | X6: PSD_Allocation | Z6: SQL | AC6: NGUYÊN NHÂN LỖ | AM6: do not edit here
B7: 9002517105101 | C7: 8 | D7: Alvorada | E7: zrnková káva | F7: 1kg | G7: 1 | H7: 275 | I7: 267.68 | J7: SELI,spol.s r.o. | K7: 1051049 | L7: 1 | O7: 32 | P7: 1 | Q7: 1 | R7: 305 | S7: COVER PAGE | T7: PKD | U7: valentýn | V7: 1 | X7: Product_01 | Y7: =COUNTIF(K:K,K7) -> 1 | AA7: =H7-I7 -> 7.32 | AB7: =R7-H7 -> 30
B8: 4006067060977 | C8: 6 | D8: Davidoff | E8: instantí káva | F8: 90g, 100g | G8: 4 | H8: 125 | I8: 120.46 | J8: Tchibo Praha, spol. s r.o. | K8: 1040048 | L8: 1 | O8: 70 | P8: 2 | Q8: 2 | R8: 135 | S8: COVER PAGE | T8: PKD | U8: valentýn | V8: 1 | X8: Product_02 | Y8: =COUNTIF(K:K,K8) -> 1 | AA8: =H8-I8 -> 4.54 | AB8: =R8-H8 -> 10
B9: 5908243700532 | C9: 20 | D9: Lindt Lindor | E9: srdce tin | F9: 50g | G9: 1 | H9: 48.9 | I9: 47.6 | J9: Lindt & Sprüngli (Czechia) s.r.o. | K9: 2017390 | L9: 2 | O9: 182 | P9: 1 | Q9: 1 | R9: 56.9 | S9: COVER PAGE | T9: PKD | U9: valentýn | V9: 1 | X9: Product_03 | Y9: =COUNTIF(K:K,K9) -> 1 | AA9: =H9-I9 -> 1.3 | AB9: =R9-H9 -> 8
B10: 4000539398469 | C10: 6 | D10: Lindt Pralines Hochfein | E10: bonboniéra | F10: 120g | G10: 1 | H10: 145 | I10: 139.24 | J10: Lindt & Sprüngli (Czechia) s.r.o. | K10: 2015994 | L10: 1 | O10: 133 | P10: 0 | Q10: 1 | R10: 159 | S10: COVER PAGE | T10: PKD | U10: valentýn | V10: 1 | X10: Product_04 | Y10: =COUNTIF(K:K,K10) -> 1 | AA10: =H10-I10 -> 5.76 | AB10: =R10-H10 -> 14
B11: 8699462609924 | C11: 24 | D11: Lexus srdce | E11: bonboniéra | F11: 110g | G11: 2 | H11: 28.9 | I11: 27.94 | J11: VIOLET KANGAROO s.r.o. | K11: 2115158 | L11: 1 | O11: 490 | P11: 1 | Q11: 1 | R11: 31.9 | S11: COVER PAGE | T11: PKD | U11: valentýn | V11: 1 | X11: Product_05 | Y11: =COUNTIF(K:K,K11) -> 1 | AA11: =H11-I11 -> 0.96 | AB11: =R11-H11 -> 3
B12: 8699462608392 | C12: 12 | D12: Lexus | E12: bonboniéra | F12: 150g | G12: 3 | H12: 52.9 | I12: 51.46 | J12: VIOLET KANGAROO s.r.o. | K12: 2016775 | L12: 1 | O12: 200 | P12: 1 | Q12: 1 | R12: 59.9 | S12: COVER PAGE | T12: PKD | U12: valentýn | V12: 1 | X12: Product_06 | Y12: =COUNTIF(K:K,K12) -> 1 | AA12: =H12-I12 -> 1.44 | AB12: =R12-H12 -> 7
B13: 5901177153689 | C13: 6 | D13: Vobro Love and Cherry | E13: bonboniéra | F13: 300g | G13: 1 | H13: 122.9 | I13: 119.73 | J13: VÁCLAV NOVÁK TOP CUKROVINKY #KS | K13: 2013590 | L13: 1 | O13: 85 | P13: 1 | Q13: 1 | R13: 137.9 | S13: COVER PAGE | T13: PKD | U13: valentýn | V13: 1 | X13: Product_08 | Y13: =COUNTIF(K:K,K13) -> 1 | AA13: =H13-I13 -> 3.17 | AB13: =R13-H13 -> 15
S14: COVER PAGE | T14: PKD | V14: 1 | Y14: =COUNTIF(K:K,K14) -> 0 | AA14: =H14-I14 -> 0 | AB14: =R14-H14 -> 0
B15: 7622210928603 | C15: 12 | D15: Milka | E15: pralines | F15: 44g | G15: 2 | H15: 32.9 | I15: 31.67 | J15: VIMPEX DRINK Kft. #KS | K15: 2013640 | O15: 2184 | P15: 2 | Q15: 2 | R15: 37.9 | S15: HERO | T15: PKD | U15: čokoládový týden | V15: 2 | Y15: =COUNTIF(K:K,K15) -> 1 | AA15: =H15-I15 -> 1.23 | AB15: =R15-H15 -> 5
B16: 7622210594785 | C16: 10 | D16: Milka | E16: pralines | F16: 110g | G16: 4 | H16: 52.9 | I16: 51.09 | J16: VIMPEX DRINK Kft. #KS | K16: 2019100 | O16: 893 | P16: 2 | Q16: 2 | R16: 59.9 | S16: HERO | T16: PKD | U16: čokoládový týden | V16: 2 | Y16: =COUNTIF(K:K,K16) -> 1 | AA16: =H16-I16 -> 1.81 | AB16: =R16-H16 -> 7
B17: 8000500023976 | C17: 6 | D17: Raffaello | E17: T15 | F17: 150g | G17: 1 | H17: 64.9 | I17: 63.14 | J17: VIMPEX DRINK Kft. #KS | K17: 2010640 | O17: 7239 | P17: 2 | Q17: 2 | R17: 65.9 | S17: HERO | T17: PKD | U17: čokoládový týden | V17: 2 | Y17: =COUNTIF(K:K,K17) -> 1 | AA17: =H17-I17 -> 1.76 | AB17: =R17-H17 -> 1
B18: 40084084 | C18: 15 | D18: Mon Cheri | E18: T5 | F18: 52,5g | G18: 1 | H18: 26.9 | I18: 25.97 | J18: VIMPEX DRINK Kft. #KS | K18: 2014744 | O18: 3839 | P18: 2 | Q18: 2 | R18: 28.9 | S18: HERO | T18: PKD | U18: čokoládový týden | V18: 2 | Y18: =COUNTIF(K:K,K18) -> 1 | AA18: =H18-I18 -> 0.93 | AB18: =R18-H18 -> 2
B19: 4008400101521 | C19: 8 | D19: Mon Cheri | E19: T10 | F19: 105g | G19: 1 | H19: 57.9 | I19: 56.32 | J19: VIMPEX DRINK Kft. #KS | K19: 2014742 | O19: 276 | P19: 2 | Q19: 2 | R19: 65.9 | S19: HERO | T19: PKD | U19: čokoládový týden | V19: 2 | Y19: =COUNTIF(K:K,K19) -> 1 | AA19: =H19-I19 -> 1.58 | AB19: =R19-H19 -> 8
B20: 8000500192801 | C20: 8 | D20: Ferrero Rocher | E20: T8 | F20: 100g | G20: 1 | H20: 61.9 | I20: 59.63 | J20: VIMPEX DRINK Kft. #KS | K20: 2015661 | O20: 3862 | P20: 2 | Q20: 2 | R20: 69.9 | S20: HERO | T20: PKD | U20: čokoládový týden | V20: 2 | Y20: =COUNTIF(K:K,K20) -> 1 | AA20: =H20-I20 -> 2.27 | AB20: =R20-H20 -> 8
B21: 5901177158516 | C21: 14 | D21: Vobro Ego | E21: pralines | F21: od 87g - 92g | G21: všechny | H21: 39.9 | I21: 38.64 | J21: VÁCLAV NOVÁK TOP CUKROVINKY #KS | K21: 2115906 | O21: 122 | P21: 1 | Q21: 1 | R21: 44.9 | S21: HERO | T21: PKD | U21: čokoládový týden | V21: 2 | Y21: =COUNTIF(K:K,K21) -> 1 | AA21: =H21-I21 -> 1.26 | AB21: =R21-H21 -> 5
S22: HERO | T22: PKD | U22: čokoládový týden | V22: 2 | Y22: =COUNTIF(K:K,K22) -> 0 | AA22: =H22-I22 -> 0 | AB22: =R22-H22 -> 0
S23: HERO | T23: PKD | U23: čokoládový týden | V23: 2 | Y23: =COUNTIF(K:K,K23) -> 0 | AA23: =H23-I23 -> 0 | AB23: =R23-H23 -> 0
S24: HERO | T24: PKD | U24: čokoládový týden | V24: 2 | Y24: =COUNTIF(K:K,K24) -> 0 | AA24: =H24-I24 -> 0 | AB24: =R24-H24 -> 0
S25: HERO | T25: PKD | U25: čokoládový týden | V25: 2 | Y25: =COUNTIF(K:K,K25) -> 0 | AA25: =H25-I25 -> 0 | AB25: =R25-H25 -> 0
S26: HERO | T26: PKD | U26: čokoládový týden | V26: 2 | Y26: =COUNTIF(K:K,K26) -> 0 | AA26: =H26-I26 -> 0 | AB26: =R26-H26 -> 0
S27: SEZÓNNÍ BLOK | T27: PKD | V27: 3 | Y27: =COUNTIF(K:K,K27) -> 0 | AA27: =H27-I27 -> 0 | AB27: =R27-H27 -> 0
S28: SEZÓNNÍ BLOK | T28: PKD | V28: 3 | Y28: =COUNTIF(K:K,K28) -> 0 | AA28: =H28-I28 -> 0 | AB28: =R28-H28 -> 0
S29: SEZÓNNÍ BLOK | T29: PKD | V29: 3 | Y29: =COUNTIF(K:K,K29) -> 0 | AA29: =H29-I29 -> 0 | AB29: =R29-H29 -> 0
S30: SEZÓNNÍ BLOK | T30: PKD | V30: 3 | Y30: =COUNTIF(K:K,K30) -> 0 | AA30: =H30-I30 -> 0 | AB30: =R30-H30 -> 0
S31: SEZÓNNÍ BLOK | T31: PKD | V31: 3 | Y31: =COUNTIF(K:K,K31) -> 0 | AA31: =H31-I31 -> 0 | AB31: =R31-H31 -> 0
D32: cancel page 3 | S32: SEZÓNNÍ BLOK | T32: PKD | V32: 3 | Y32: =COUNTIF(K:K,K32) -> 0 | AA32: =H32-I32 -> 0 | AB32: =R32-H32 -> 0
S33: SEZÓNNÍ BLOK | T33: PKD | V33: 3 | Y33: =COUNTIF(K:K,K33) -> 0 | AA33: =H33-I33 -> 0 | AB33: =R33-H33 -> 0
S34: SEZÓNNÍ BLOK | T34: PKD | V34: 3 | Y34: =COUNTIF(K:K,K34) -> 0 | AA34: =H34-I34 -> 0 | AB34: =R34-H34 -> 0
S35: SEZÓNNÍ BLOK | T35: PKD | V35: 3 | Y35: =COUNTIF(K:K,K35) -> 0 | AA35: =H35-I35 -> 0 | AB35: =R35-H35 -> 0
S36: SEZÓNNÍ BLOK | T36: PKD | V36: 3 | Y36: =COUNTIF(K:K,K36) -> 0 | AA36: =H36-I36 -> 0 | AB36: =R36-H36 -> 0
S37: SEZÓNNÍ BLOK | T37: PKD | V37: 3 | Y37: =COUNTIF(K:K,K37) -> 0 | AA37: =H37-I37 -> 0 | AB37: =R37-H37 -> 0
S38: SEZÓNNÍ BLOK | T38: PKD | V38: 3 | Y38: =COUNTIF(K:K,K38) -> 0 | AA38: =H38-I38 -> 0 | AB38: =R38-H38 -> 0
S39: SEZÓNNÍ BLOK | T39: PKD | V39: 4 | Y39: =COUNTIF(K:K,K39) -> 0 | AA39: =H39-I39 -> 0 | AB39: =R39-H39 -> 0
S40: SEZÓNNÍ BLOK | T40: PKD | V40: 4 | Y40: =COUNTIF(K:K,K40) -> 0 | AA40: =H40-I40 -> 0 | AB40: =R40-H40 -> 0
...
